Workbook

Sheet Master Data
A1: Employee ID | B1: Name | C1: Department | D1: Position | E1: Entry Date | F1: FTE | G1: Cost Center | H1: Status
A2: 144 | C2: Счетоводство | D2: Старши счетоводител | E2: 40361 | F2: 1 | G2: 5400 | H2: Active
A3: 66 | C3: Заваръчно | D3: Заварчик | E3: 41387 | F3: 1 | G3: 1400 | H3: Active | J3: Row Labels | K3: Count of Name
A4: 748 | C4: Преси | D4: Оператор, преса за метал | E4: 46034 | F4: 1 | G4: 1200 | H4: Inactive | J4: Автоматизация | K4: 6
A5: 753 | C5: Монтаж | D5: Машинен оператор | E5: 46062 | F5: 1 | G5: 1600 | H5: Active | J5: Дизайн на автоматизация | K5: 2
A6: 747 | C6: Монтаж | D6: Монтажник, изделия от метал | E6: 46029 | F6: 1 | G6: 1600 | H6: Active | J6: Дизайн на инструменти | K6: 2
A7: 648 | C7: Механична обработка | D7: Машинен оператор, металообработващи машини | E7: 44845 | F7: 1 | G7: 1300 | H7: Active | J7: Заваръчно | K7: 5
A8: 263 | C8: Калкулация | D8: Технолог | E8: 41821 | F8: 1 | G8: 4400 | H8: Active | J8: Заготовки за производство | K8: 2
A9: 719 | C9: ТРАНСПОРТ | D9: Шофьор, лекотоварен автомобил | E9: 45670 | F9: 1 | G9: 3900 | H9: Active | J9: Инструментален отдел | K9: 11
A10: 67 | C10: Механична обработка | D10: Настройчик, металообработващи машини с цифрово управление | E10: 41334 | F10: 1 | G10: 1300 | H10: Active | J10: Калкулация | K10: 2
A11: 615 | C11: Преси | D11: Машинен оператор, металообработващи машини | E11: 44634 | F11: 1 | G11: 1200 | H11: Active | J11: Механична обработка | K11: 23
A12: 465 | C12: Инструментален отдел | D12: Матричар | E12: 43412 | F12: 1 | G12: 2100 | H12: Active | J12: Монтаж | K12: 46
A13: 608 | C13: Монтаж | D13: Монтажник, изделия от метал | E13: 44593 | F13: 1 | G13: 1600 | H13: Active | J13: Общи IT | K13: 2
A14: 55 | C14: Преси | D14: Оператор, преса за метал | E14: 41535 | F14: 1 | G14: 1200 | H14: Active | J14: Осигуряване на качеството | K14: 5
A15: 6 | C15: Монтаж | D15: Монтажник, изделия от метал | E15: 38687 | F15: 1 | G15: 1600 | H15: Active | J15: Поддръжка машини | K15: 2
... A30: 726 | C30: Монтаж | D30: Машинен оператор | E30: 45804 | F30: 1 | G30: 1600 | H30: Active | J30: Grand Total | K30: 154
A31: 231 | C31: Развойна дейност | D31: Инженер, конструктор | E31: 41535 | F31: 1 | G31: 4500 | H31: Active
A32: 610 | C32: Механична обработка | D32: Настройчик, металообработващи машини с цифрово управление | E32: 44628 | F32: 1 | G32: 1300 | H32: Active
A33: 751 | C33: Механична обработка | D33: Настройчик, металообработващи машини с цифрово управление | E33: 46055 | F33: 1 | G33: 1300 | H33: Active
A34: 623 | C34: Инструментален отдел | D34: Машинен оператор, металообработващи машини | E34: 44691 | F34: 1 | G34: 2100 | H34: Active
A35: 745 | C35: Механична обработка | D35: Настройчик, металообработващи машини | E35: 45992 | F35: 1 | G35: 1300 | H35: Active
A36: 756 | C36: Монтаж | D36: Монтажник, изделия от метал | E36: 46076 | F36: 1 | G36: 1600 | H36: Active
A37: 404 | C37: Монтаж | D37: Монтажник, изделия от метал | E37: 42772 | F37: 1 | G37: 1600 | H37: Active
A38: 277 | C38: Преси | D38: Настройчик, пресови металообработващи машини | E38: 41885 | F38: 1 | G38: 1200 | H38: Active
A39: 644 | C39: Осигуряване на качеството | D39: Инженер, качество | E39: 44838 | F39: 1 | G39: 3500 | H39: Active
A40: 472 | C40: Инструментален отдел | D40: Машинен оператор, металообработващи машини | E40: 43479 | F40: 1 | G40: 2100 | H40: Active
A41: 542 | C41: Механична обработка | D41: Машинен оператор, металообработващи машини | E41: 43896 | F41: 1 | G41: 1300 | H41: Active
A42: 494 | C42: Осигуряване на качеството | D42: Окачествител, продукти (без храни и напитки) | E42: 43647 | F42: 1 | G42: 3500 | H42: Active
... A155: 12 | C155: Общи IT | D155: Администратор, информационни системи | E155: 38852 | F155: 1 | G155: 5600 | H155: Active

Sheet Salary History
A1: Employee ID | B1: Effective Date | C1: Name | D1: Cost Center | E1: Department | F1: Base Salary (Gross) | G1: Professional experience (Gross) | H1: Fixed Bonus (Gross) | I1: Food Vaucher | J1: Total (Gross) | K1: Salary (netto) | L1: Total Monthly Salary (netto) include food vaucher | M1: Annual Salary (netto) | N1: Month Employer Cost | O1: Annual Employer Cost | P1: % Increase | Q1: Reason | R1: Approved By | S1: Approval Date | T1: Comment | V1: Years (Effective Date) | W1: 2026
A2: 144 | B2: 46023 | D2: =VLOOKUP(C2,'Master Data'!$B$2:$G$155,6,0) -> #N/A | E2: Счетоводство | F2: 1431.62 | G2: 206.15328 | H2: 357.9 | I2: 102.26 | J2: =F2+G2+H2 -> 1995.6733 | K2: 1548.6425 | L2: =K2+I2 -> 1650.9025 | M2: =L2*12 -> 19810.83 | N2: =J2+(19.62%*(J2)+I2) -> 2489.4844 | O2: =N2*12 -> 29873.813 | V2: Months (Effective Date) | W2: (All)
A3: 66 | B3: 46023 | D3: =VLOOKUP(C3,'Master Data'!$B$2:$G$155,6,0) -> #N/A | E3: Заваръчно | F3: 639.12 | G3: 46.01664 | H3: 546.57 | I3: 102.26 | J3: =F3+G3+H3 -> 1231.7066 | K3: 955.80435 | L3: =K3+I3 -> 1058.0644 | M3: =L3*12 -> 12696.772 | N3: =J3+(19.62%*(J3)+I3) -> 1575.6275 | O3: =N3*12 -> 18907.53 | V3: Effective Date | W3: (All)
A4: 748 | B4: 46023 | D4: =VLOOKUP(C4,'Master Data'!$B$2:$G$155,6,0) -> #N/A | E4: Преси | F4: 675.01 | G4: 0 | H4: 412.2 | I4: 102.26 | J4: =F4+G4+H4 -> 1087.21 | K4: 843.67496 | L4: =K4+I4 -> 945.93496 | M4: =L4*12 -> 11351.22 | N4: =J4+(19.62%*(J4)+I4) -> 1402.7806 | O4: =N4*12 -> 16833.367 | V4: Quarters (Effective Date) | W4: (All)
A5: 753 | B5: 46023 | D5: =VLOOKUP(C5,'Master Data'!$B$2:$G$155,6,0) -> #N/A | E5: Монтаж | F5: 737 | G5: 0 | H5: 123.84 | I5: 102.26 | J5: =F5+G5+H5 -> 860.84 | K5: 668.01184 | L5: =K5+I5 -> 770.27184 | M5: =L5*12 -> 9243.2621 | N5: =J5+(19.62%*(J5)+I5) -> 1131.9968 | O5: =N5*12 -> 13583.962
A6: 747 | B6: 46023 | D6: =VLOOKUP(C6,'Master Data'!$B$2:$G$155,6,0) -> #N/A | E6: Монтаж | F6: 639.12 | G6: 0 | H6: 85.67 | I6: 102.26 | J6: =F6+G6+H6 -> 724.79 | K6: 562.43704 | L6: =K6+I6 -> 664.69704 | M6: =L6*12 -> 7976.3645 | N6: =J6+(19.62%*(J6)+I6) -> 969.2538 | O6: =N6*12 -> 11631.046 | V6: Row Labels | W6: Sum of Month Employer Cost | X6: Sum of Annual Employer Cost | Y6: Sum of Annual Salary (netto)
A7: 648 | B7: 46023 | D7: =VLOOKUP(C7,'Master Data'!$B$2:$G$155,6,0) -> #N/A | E7: Механична обработка | F7: 741.38 | G7: 4.44828 | H7: 378.87 | I7: 102.26 | J7: =F7+G7+H7 -> 1124.6983 | K7: 872.76587 | L7: =K7+I7 -> 975.02587 | M7: =L7*12 -> 11700.31 | N7: =J7+(19.62%*(J7)+I7) -> 1447.6241 | O7: =N7*12 -> 17371.489 | V7: Автоматизация | W7: 13229.685 | X7: 158756.22 | Y7: 105824.13
A8: 263 | B8: 46023 | D8: =VLOOKUP(C8,'Master Data'!$B$2:$G$155,6,0) -> #N/A | E8: Калкулация | F8: 945.89 | G8: 90.80544 | H8: 561.4 | I8: 102.26 | J8: =F8+G8+H8 -> 1598.0954 | K8: 1240.1221 | L8: =K8+I8 -> 1342.3821 | M8: =L8*12 -> 16108.585 | N8: =J8+(19.62%*(J8)+I8) -> 2013.9018 | O8: =N8*12 -> 24166.821 | V8: Дизайн на автоматизация | W8: 6511.9751 | X8: 78143.701 | Y8: 53116.32
A9: 719 | B9: 46023 | D9: =VLOOKUP(C9,'Master Data'!$B$2:$G$155,6,0) -> #N/A | E9: ТРАНСПОРТ | F9: 741.38 | G9: 17.79312 | H9: 365.57 | I9: 102.26 | J9: =F9+G9+H9 -> 1124.7431 | K9: 872.80066 | L9: =K9+I9 -> 975.06066 | M9: =L9*12 -> 11700.728 | N9: =J9+(19.62%*(J9)+I9) -> 1447.6777 | O9: =N9*12 -> 17372.133 | V9: Дизайн на инструменти | W9: 4644.1087 | X9: 55729.304 | Y9: 37014.89
A10: 67 | B10: 46023 | D10: =VLOOKUP(C10,'Master Data'!$B$2:$G$155,6,0) -> #N/A | E10: Механична обработка | F10: 986.8 | G10: 71.0496 | H10: 277.63 | I10: 102.26 | J10: =F10+G10+H10 -> 1335.4796 | K10: 1036.3322 | L10: =K10+I10 -> 1138.5922 | M10: =L10*12 -> 13663.106 | N10: =J10+(19.62%*(J10)+I10) -> 1699.7607 | O10: =N10*12 -> 20397.128 | V10: Заваръчно | W10: 8010.9454 | X10: 96131.345 | Y10: 64517.725
A11: 615 | B11: 46023 | D11: =VLOOKUP(C11,'Master Data'!$B$2:$G$155,6,0) -> #N/A | E11: Преси | F11: 790.97 | G11: 47.4582 | H11: 269.96 | I11: 102.26 | J11: =F11+G11+H11 -> 1108.3882 | K11: 860.10924 | L11: =K11+I11 -> 962.36924 | M11: =L11*12 -> 11548.431 | N11: =J11+(19.62%*(J11)+I11) -> 1428.114 | O11: =N11*12 -> 17137.368 | V11: Заготовки за производство | W11: 3099.4301 | X11: 37193.161 | Y11: 24990.106
A12: 465 | B12: 46023 | D12: =VLOOKUP(C12,'Master Data'!$B$2:$G$155,6,0) -> #N/A | E12: Инструментален отдел | F12: 940.78 | G12: 152.40636 | H12: 175.5 | I12: 102.26 | J12: =F12+G12+H12 -> 1268.6864 | K12: 984.50062 | L12: =K12+I12 -> 1086.7606 | M12: =L12*12 -> 13041.127 | N12: =J12+(19.62%*(J12)+I12) -> 1619.8626 | O12: =N12*12 -> 19438.351 | V12: Инструментален отдел | W12: 21430.415 | X12: 257164.98 | Y12: 171774.53
A13: 608 | B13: 46023 | D13: =VLOOKUP(C13,'Master Data'!$B$2:$G$155,6,0) -> #N/A | E13: Монтаж | F13: 639.12 | G13: 26.84304 | H13: 71.86 | I13: 102.26 | J13: =F13+G13+H13 -> 737.82304 | K13: 572.55068 | L13: =K13+I13 -> 674.81068 | M13: =L13*12 -> 8097.7281 | N13: =J13+(19.62%*(J13)+I13) -> 984.84392 | O13: =N13*12 -> 11818.127 | V13: Калкулация | W13: 3465.5029 | X13: 41586.035 | Y13: 27839.855
A14: 55 | B14: 46023 | D14: =VLOOKUP(C14,'Master Data'!$B$2:$G$155,6,0) -> #N/A | E14: Преси | F14: 674.91 | G14: 48.59352 | H14: 202.21 | I14: 102.26 | J14: =F14+G14+H14 -> 925.71352 | K14: 718.35369 | L14: =K14+I14 -> 820.61369 | M14: =L14*12 -> 9847.3643 | N14: =J14+(19.62%*(J14)+I14) -> 1209.5985 | O14: =N14*12 -> 14515.182 | V14: Механична обработка | W14: 30821.385 | X14: 369856.62 | Y14: 251728.89
A15: 6 | B15: 46023 | D15: =VLOOKUP(C15,'Master Data'!$B$2:$G$155,6,0) -> #N/A | E15: Монтаж | F15: 639.12 | G15: 76.6944 | H15: 88.25 | I15: 102.26 | J15: =F15+G15+H15 -> 804.0644 | K15: 623.95397 | L15: =K15+I15 -> 726.21397 | M15: =L15*12 -> 8714.5677 | N15: =J15+(19.62%*(J15)+I15) -> 1064.0818 | O15: =N15*12 -> 12768.982 | V15: Монтаж | W15: 48656.153 | X15: 583873.83 | Y15: 397737.9
A16: 697 | B16: 46023 | D16: =VLOOKUP(C16,'Master Data'!$B$2:$G$155,6,0) -> #N/A | E16: Склад | F16: 792.51 | G16: 14.26518 | H16: 323.14 | I16: 102.26 | J16: =F16+G16+H16 -> 1129.9152 | K16: 876.81418 | L16: =K16+I16 -> 979.07418 | M16: =L16*12 -> 11748.89 | N16: =J16+(19.62%*(J16)+I16) -> 1453.8645 | O16: =N16*12 -> 17446.374 | V16: Общи IT | W16: 3965.8929 | X16: 47590.714 | Y16: 31735.216
A17: 736 | B17: 46023 | D17: =VLOOKUP(C17,'Master Data'!$B$2:$G$155,6,0) -> #N/A | E17: Механична обработка | F17: 155.95 | G17: 0 | H17: 0 | I17: 102.26 | J17: =F17+G17+H17 -> 155.95 | K17: 140.35 | L17: =K17+I17 -> 242.61 | M17: =L17*12 -> 2911.32 | N17: =J17+I17 -> 258.21 | O17: =N17*12 -> 3098.52 | V17: Осигуряване на качеството | W17: 8028.3644 | X17: 96340.373 | Y17: 64653.326
A18: 713 | B18: 46023 | D18: =VLOOKUP(C18,'Master Data'!$B$2:$G$155,6,0) -> #N/A | E18: Инструментален отдел | F18: 935.67 | G18: 39.29814 | H18: 282.74 | I18: 102.26 | J18: =F18+G18+H18 -> 1257.7081 | K18: 975.98152 | L18: =K18+I18 -> 1078.2415 | M18: =L18*12 -> 12938.898 | N18: =J18+(19.62%*(J18)+I18) -> 1606.7305 | O18: =N18*12 -> 19280.766 | V18: Поддръжка машини | W18: 3616.1466 | X18: 43393.76 | Y18: 29012.564
A19: 660 | B19: 46023 | D19: =VLOOKUP(C19,'Master Data'!$B$2:$G$155,6,0) -> #N/A | E19: Поддръжка машини | F19: 1135.07 | G19: 115.77714 | H19: 285.3 | I19: 102.26 | J19: =F19+G19+H19 -> 1536.1471 | K19: 1192.0502 | L19: =K19+I19 -> 1294.3102 | M19: =L19*12 -> 15531.722 | N19: =J19+(19.62%*(J19)+I19) -> 1939.7992 | O19: =N19*12 -> 23277.591 | V19: Покупки | W19: 4747.437 | X19: 56969.244 | Y19: 38250.326
A20: 52 | B20: 46023 | D20: =VLOOKUP(C20,'Master Data'!$B$2:$G$155,6,0) -> #N/A | E20: Инструментален отдел | F20: 915.22 | G20: 131.79168 | H20: 1068.6 | I20: 102.26 | J20: =F20+G20+H20 -> 2115.6117 | K20: 1642.16 | L20: =K20+I20 -> 1744.42 | M20: =L20*12 -> 20933.04 | N20: =J20+(19.62%*(J20)+I20) -> 2632.9547 | O20: =N20*12 -> 31595.456 | V20: Преси | W20: 19607.895 | X20: 235294.74 | Y20: 158063.07
A21: 673 | B21: 46023 | D21: =VLOOKUP(C21,'Master Data'!$B$2:$G$155,6,0) -> #N/A | E21: Монтаж | F21: 737 | G21: 8.844 | H21: 242.51 | I21: 102.26 | J21: =F21+G21+H21 -> 988.354 | K21: 766.9627 | L21: =K21+I21 -> 869.2227 | M21: =L21*12 -> 10430.672 | N21: =J21+(19.62%*(J21)+I21) -> 1284.5291 | O21: =N21*12 -> 15414.349 | V21: Производство | W21: 9651.408 | X21: 115816.9 | Y21: 79598.374
A22: 580 | B22: 46023 | D22: =VLOOKUP(C22,'Master Data'!$B$2:$G$155,6,0) -> #N/A | E22: Автоматизация | F22: 1037.93 | G22: 56.04822 | H22: 777.16 | I22: 102.26 | J22: =F22+G22+H22 -> 1871.1382 | K22: 1452.0033 | L22: =K22+I22 -> 1554.2633 | M22: =L22*12 -> 18651.159 | N22: =J22+(19.62%*(J22)+I22) -> 2340.5155 | O22: =N22*12 -> 28086.186 | V22: Развойна дейност | W22: 2432.6107 | X22: 29191.329 | Y22: 19368.088
A23: 682 | B23: 46023 | D23: =VLOOKUP(C23,'Master Data'!$B$2:$G$155,6,0) -> #N/A | E23: Монтаж | F23: 639.12 | G23: 65.19024 | H23: 126.98 | I23: 102.26 | J23: =F23+G23+H23 -> 831.29024 | K23: 645.08123 | L23: =K23+I23 -> 747.34123 | M23: =L23*12 -> 8968.0947 | N23: =J23+(19.62%*(J23)+I23) -> 1096.6494 | O23: =N23*12 -> 13159.793 | V23: Сгради | W23: 3351.8037 | X23: 40221.644 | Y23: 27385.808
A24: 566 | B24: 46023 | D24: =VLOOKUP(C24,'Master Data'!$B$2:$G$155,6,0) -> #N/A | E24: Монтаж | F24: 639.12 | G24: 53.68608 | H24: 58.25 | I24: 102.26 | J24: =F24+G24+H24 -> 751.05608 | K24: 582.81952 | L24: =K24+I24 -> 685.07952 | M24: =L24*12 -> 8220.9542 | N24: =J24+(19.62%*(J24)+I24) -> 1000.6733 | O24: =N24*12 -> 12008.079 | V24: Склад | W24: 5789.9643 | X24: 69479.571 | Y24: 46797.1
A25: 708 | B25: 46023 | D25: =VLOOKUP(C25,'Master Data'!$B$2:$G$155,6,0) -> #N/A | E25: Автоматизация | F25: 1237.33 | G25: 74.2398 | H25: 343.59 | I25: 102.26 | J25: =F25+G25+H25 -> 1655.1598 | K25: 1284.404 | L25: =K25+I25 -> 1386.664 | M25: =L25*12 -> 16639.968 | N25: =J25+(19.62%*(J25)+I25) -> 2082.1622 | O25: =N25*12 -> 24985.946 | V25: Спедиция | W25: 5294.1013 | X25: 63529.215 | Y25: 42505.918
A26: 368 | B26: 46023 | D26: =VLOOKUP(C26,'Master Data'!$B$2:$G$155,6,0) -> #N/A | E26: Механична обработка | F26: 741.38 | G26: 40.03452 | H26: 209.63 | I26: 102.26 | J26: =F26+G26+H26 -> 991.04452 | K26: 769.05055 | L26: =K26+I26 -> 871.31055 | M26: =L26*12 -> 10455.727 | N26: =J26+(19.62%*(J26)+I26) -> 1287.7475 | O26: =N26*12 -> 15452.969 | V26: Счетоводство | W26: 6983.7661 | X26: 83805.193 | Y26: 55658.828
A27: 239 | B27: 46023 | D27: =VLOOKUP(C27,'Master Data'!$B$2:$G$155,6,0) -> #N/A | E27: Заваръчно | F27: 838.52 | G27: 60.37344 | H27: 248.67 | I27: 102.26 | J27: =F27+G27+H27 -> 1147.5634 | K27: 890.50923 | L27: =K27+I27 -> 992.76923 | M27: =L27*12 -> 11913.231 | N27: =J27+(19.62%*(J27)+I27) -> 1474.9754 | O27: =N27*12 -> 17699.705 | V27: ТРАНСПОРТ | W27: 1447.6777 | X27: 17372.133 | Y27: 11700.728
A28: 741 | B28: 46023 | D28: =VLOOKUP(C28,'Master Data'!$B$2:$G$155,6,0) -> #N/A | E28: Монтаж | F28: 690.25 | G28: 0 | H28: 232.64 | I28: 102.26 | J28: =F28+G28+H28 -> 922.89 | K28: 716.16264 | L28: =K28+I28 -> 818.42264 | M28: =L28*12 -> 9821.0717 | N28: =J28+(19.62%*(J28)+I28) -> 1206.221 | O28: =N28*12 -> 14474.652 | V28: Управление на качеството | W28: 3867.5615 | X28: 46410.738 | Y28: 32079.84
A29: 738 | B29: 46023 | D29: =VLOOKUP(C29,'Master Data'!$B$2:$G$155,6,0) -> #N/A | E29: Механична обработка | F29: 792.51 | G29: 57.06072 | H29: 205.03 | I29: 102.26 | J29: =F29+G29+H29 -> 1054.6007 | K29: 818.37016 | L29: =K29+I29 -> 920.63016 | M29: =L29*12 -> 11047.562 | N29: =J29+(19.62%*(J29)+I29) -> 1363.7734 | O29: =N29*12 -> 16365.281 | V29: Управление на проекти | W29: 12211.333 | X29: 146536 | Y29: 101734.56
... A33: 751 | B33: 46023 | D33: =VLOOKUP(C33,'Master Data'!$B$2:$G$155,6,0) -> #N/A | E33: Механична обработка | F33: 987 | G33: 0 | H33: 265.68 | I33: 102.26 | J33: =F33+G33+H33 -> 1252.68 | K33: 972.07968 | L33: =K33+I33 -> 1074.3397 | M33: =L33*12 -> 12892.076 | N33: =J33+(19.62%*(J33)+I33) -> 1600.7158 | O33: =N33*12 -> 19208.59 | V33: Grand Total | W33: 248268.61 | X33: 2979223.4 | Y33: 2012524.5
A34: 623 | B34: 46023 | D34: =VLOOKUP(C34,'Master Data'!$B$2:$G$155,6,0) -> #N/A | E34: Инструментален отдел | F34: 715.81 | G34: 12.88458 | H34: 856.93 | I34: 102.26 | J34: =F34+G34+H34 -> 1585.6246 | K34: 1230.4447 | L34: =K34+I34 -> 1332.7047 | M34: =L34*12 -> 15992.456 | N34: =J34+(19.62%*(J34)+I34) -> 1998.9841 | O34: =N34*12 -> 23987.809
A35: 745 | B35: 46023 | D35: =VLOOKUP(C35,'Master Data'!$B$2:$G$155,6,0) -> #N/A | E35: Механична обработка | F35: 1083.94 | G35: 32.5182 | H35: 333.36 | I35: 102.26 | J35: =F35+G35+H35 -> 1449.8182 | K35: 1125.0589 | L35: =K35+I35 -> 1227.3189 | M35: =L35*12 -> 14727.827 | N35: =J35+(19.62%*(J35)+I35) -> 1836.5325 | O35: =N35*12 -> 22038.39
A36: 756 | B36: 46023 | D36: =VLOOKUP(C36,'Master Data'!$B$2:$G$155,6,0) -> #N/A | E36: Монтаж | F36: 640 | G36: 0 | H36: 85.53 | I36: 102.26 | J36: =F36+G36+H36 -> 725.53 | K36: 563.01128 | L36: =K36+I36 -> 665.27128 | M36: =L36*12 -> 7983.2554 | N36: =J36+(19.62%*(J36)+I36) -> 970.13899 | O36: =N36*12 -> 11641.668 | V36: Years (Effective Date) | W36: 2026
A37: 404 | B37: 46023 | D37: =VLOOKUP(C37,'Master Data'!$B$2:$G$155,6,0) -> #N/A | E37: Монтаж | F37: 639.12 | G37: 30.67776 | H37: 88.25 | I37: 102.26 | J37: =F37+G37+H37 -> 758.04776 | K37: 588.24506 | L37: =K37+I37 -> 690.50506 | M37: =L37*12 -> 8286.0607 | N37: =J37+(19.62%*(J37)+I37) -> 1009.0367 | O37: =N37*12 -> 12108.441 | V37: Quarters (Effective Date) | W37: (All)
A38: 277 | B38: 46023 | D38: =VLOOKUP(C38,'Master Data'!$B$2:$G$155,6,0) -> #N/A | E38: Преси | F38: 664.68 | G38: 43.86888 | H38: 887.6 | I38: 102.26 | J38: =F38+G38+H38 -> 1596.1489 | K38: 1238.6115 | L38: =K38+I38 -> 1340.8715 | M38: =L38*12 -> 16090.458 | N38: =J38+(19.62%*(J38)+I38) -> 2011.5733 | O38: =N38*12 -> 24138.879 | V38: Months (Effective Date) | W38: (All)
A39: 644 | B39: 46023 | D39: =VLOOKUP(C39,'Master Data'!$B$2:$G$155,6,0) -> #N/A | E39: Осигуряване на качеството | F39: 971.46 | G39: 69.94512 | H39: 0 | I39: 102.26 | J39: =F39+G39+H39 -> 1041.4051 | K39: 808.13037 | L39: =K39+I39 -> 910.39037 | M39: =L39*12 -> 10924.684 | N39: =J39+(19.62%*(J39)+I39) -> 1347.9888 | O39: =N39*12 -> 16175.866 | V39: Effective Date | W39: (All)
A40: 472 | B40: 46023 | D40: =VLOOKUP(C40,'Master Data'!$B$2:$G$155,6,0) -> #N/A | E40: Инструментален отдел | F40: 715.81 | G40: 42.9486 | H40: 414.15 | I40: 102.26 | J40: =F40+G40+H40 -> 1172.9086 | K40: 910.17707 | L40: =K40+I40 -> 1012.4371 | M40: =L40*12 -> 12149.245 | N40: =J40+(19.62%*(J40)+I40) -> 1505.2933 | O40: =N40*12 -> 18063.519
A41: 542 | B41: 46023 | D41: =VLOOKUP(C41,'Master Data'!$B$2:$G$155,6,0) -> #N/A | E41: Механична обработка | F41: 790.97 | G41: 23.7291 | H41: 381.42 | I41: 102.26 | J41: =F41+G41+H41 -> 1196.1191 | K41: 928.18842 | L41: =K41+I41 -> 1030.4484 | M41: =L41*12 -> 12365.381 | N41: =J41+(19.62%*(J41)+I41) -> 1533.0577 | O41: =N41*12 -> 18396.692 | V41: Row Labels | W41: Sum of Month Employer Cost | X41: Sum of Annual Employer Cost | Y41: Sum of Annual Salary (netto)
A42: 494 | B42: 46023 | D42: =VLOOKUP(C42,'Master Data'!$B$2:$G$155,6,0) -> #N/A | E42: Осигуряване на качеството | F42: 792.51 | G42: 42.79554 | H42: 499.53 | I42: 102.26 | J42: =F42+G42+H42 -> 1334.8355 | K42: 1035.8324 | L42: =K42+I42 -> 1138.0924 | M42: =L42*12 -> 13657.109 | N42: =J42+(19.62%*(J42)+I42) -> 1698.9903 | O42: =N42*12 -> 20387.883 | V42: 1000 | W42: 9651.408 | X42: 115816.9 | Y42: 79598.374
A43: 677 | B43: 46023 | D43: =VLOOKUP(C43,'Master Data'!$B$2:$G$155,6,0) -> #N/A | E43: Шприцоване | F43: 639.12 | G43: 80.52912 | H43: 280.19 | I43: 102.26 | J43: =F43+G43+H43 -> 999.83912 | K43: 775.87516 | L43: =K43+I43 -> 878.13516 | M43: =L43*12 -> 10537.622 | N43: =J43+(19.62%*(J43)+I43) -> 1298.2676 | O43: =N43*12 -> 15579.211 | V43: 1100 | W43: 3099.4301 | X43: 37193.161 | Y43: 24990.106
...

Sheet Monthly Budget Control
A1: Month | B1: Department | C1: Cost Center | D1: Approved Annual Budget (netto) | E1: Approved Monthly Budget (netto) | F1: Actual Payroll (netto) | G1: Variance | H1: Variance %
A2: 2 | B2: Автоматизация | C2: 2200 | D2: 105824.13 | E2: =D2/12 -> 8818.6778 | F2: 8517.6 | G2: =F2-E2 -> -301.07783 | H2: =(F2-E2)/E2 -> -0.034140926
A3: 2 | B3: Дизайн на автоматизация | C3: 2400 | D3: 53116.32 | E3: =D3/12 -> 4426.36 | F3: 4426.36 | G3: =F3-E3 -> 0 | H3: =(F3-E3)/E3 -> 0
A4: 2 | B4: Дизайн на инструменти | C4: 2410 | D4: 37014.89 | E4: =D4/12 -> 3084.5742 | F4: 2939.06 | G4: =F4-E4 -> -145.51419 | H4: =(F4-E4)/E4 -> -0.047174807
A5: 2 | B5: Заваръчно | C5: 1400 | D5: 64517.725 | E5: =D5/12 -> 5376.4771 | F5: 5783.46 | G5: =F5-E5 -> 406.98288 | H5: =(F5-E5)/E5 -> 0.075696943
A6: 2 | B6: Заготовки за производство | C6: 1100 | D6: 24990.106 | E6: =D6/12 -> 2082.5088 | F6: 2096.89 | G6: =F6-E6 -> 14.3812 | H6: =(F6-E6)/E6 -> 0.006905709
A7: 2 | B7: Инструментален отдел | C7: 2100 | D7: 171774.53 | E7: =D7/12 -> 14314.544 | F7: 14328.72 | G7: =F7-E7 -> 14.176235 | H7: =(F7-E7)/E7 -> 0.00099033787
A8: 2 | B8: Калкулация | C8: 4400 | D8: 27839.855 | E8: =D8/12 -> 2319.9879 | F8: 2301.57 | G8: =F8-E8 -> -18.417909 | H8: =(F8-E8)/E8 -> -0.0079387954
A9: 2 | B9: Механична обработка | C9: 1300 | D9: 251728.89 | E9: =D9/12 -> 20977.407 | F9: 20344.11 | G9: =F9-E9 -> -633.29733 | H9: =(F9-E9)/E9 -> -0.030189495
A10: 2 | B10: Монтаж | C10: 1600 | D10: 397737.9 | E10: =D10/12 -> 33144.825 | F10: 36614.5 | G10: =F10-E10 -> 3469.6753 | H10: =(F10-E10)/E10 -> 0.10468226
A11: 2 | B11: Общи IT | C11: 5600 | D11: 31735.216 | E11: =D11/12 -> 2644.6014 | F11: 2629.77 | G11: =F11-E11 -> -14.831374 | H11: =(F11-E11)/E11 -> -0.0056081699
A12: 2 | B12: Осигуряване на качеството | C12: 3500 | D12: 64653.326 | E12: =D12/12 -> 5387.7772 | F12: 4579.54 | G12: =F12-E12 -> -808.23717 | H12: =(F12-E12)/E12 -> -0.1500131
A13: 2 | B13: Поддръжка машини | C13: 6410 | D13: 29012.564 | E13: =D13/12 -> 2417.7137 | F13: 2417.66 | G13: =F13-E13 -> -0.0536712 | H13: =(F13-E13)/E13 -> -2.2199155e-05
... A27: 2 | B27: Продажби | C27: 4100 | D27: 14780.234 | E27: =D27/12 -> 1231.6862 | F27: 1231.66 | G27: =F27-E27 -> -0.0261736 | H27: =(F27-E27)/E27 -> -2.1250218e-05

Sheet Monthly Release
A1: Month | B1: Department | C1: Cost Center | D1: Total Payroll | E1: Budget | F1: Variance | G1: Variance % | H1: Release Status (Yes/No) | I1: Released By | J1: Release Date
A2: 2 | B2: Автоматизация | C2: 2200 | D2: 8517.6 | E2: 8818.6778 | F2: =D2-E2 -> -301.07783 | G2: =(D2-E2)/E2 -> -0.034140926
A3: 2 | B3: Дизайн на автоматизация | C3: 2400 | D3: 4426.36 | E3: 4426.36 | F3: =D3-E3 -> 0 | G3: =(D3-E3)/E3 -> 0
A4: 2 | B4: Дизайн на инструменти | C4: 2410 | D4: 2939.06 | E4: 3084.5742 | F4: =D4-E4 -> -145.51419 | G4: =(D4-E4)/E4 -> -0.047174807
A5: 2 | B5: Заваръчно | C5: 1400 | D5: 5783.46 | E5: 5376.4771 | F5: =D5-E5 -> 406.98288 | G5: =(D5-E5)/E5 -> 0.075696943
A6: 2 | B6: Заготовки за производство | C6: 1100 | D6: 2096.89 | E6: 2082.5088 | F6: =D6-E6 -> 14.3812 | G6: =(D6-E6)/E6 -> 0.006905709
A7: 2 | B7: Инструментален отдел | C7: 2100 | D7: 14328.72 | E7: 14314.544 | F7: =D7-E7 -> 14.176235 | G7: =(D7-E7)/E7 -> 0.00099033787
A8: 2 | B8: Калкулация | C8: 4400 | D8: 2301.57 | E8: 2319.9879 | F8: =D8-E8 -> -18.417909 | G8: =(D8-E8)/E8 -> -0.0079387954
A9: 2 | B9: Механична обработка | C9: 1300 | D9: 20344.11 | E9: 20977.407 | F9: =D9-E9 -> -633.29733 | G9: =(D9-E9)/E9 -> -0.030189495
A10: 2 | B10: Монтаж | C10: 1600 | D10: 36614.5 | E10: 33144.825 | F10: =D10-E10 -> 3469.6753 | G10: =(D10-E10)/E10 -> 0.10468226
A11: 2 | B11: Общи IT | C11: 5600 | D11: 2629.77 | E11: 2644.6014 | F11: =D11-E11 -> -14.831374 | G11: =(D11-E11)/E11 -> -0.0056081699
A12: 2 | B12: Осигуряване на качеството | C12: 3500 | D12: 4579.54 | E12: 5387.7772 | F12: =D12-E12 -> -808.23717 | G12: =(D12-E12)/E12 -> -0.1500131
A13: 2 | B13: Поддръжка машини | C13: 6410 | D13: 2417.66 | E13: 2417.7137 | F13: =D13-E13 -> -0.0536712 | G13: =(D13-E13)/E13 -> -2.2199155e-05
... A27: 2 | B27: Продажби | C27: 4100 | D27: 1231.66 | E27: 1231.6862 | F27: =D27-E27 -> -0.0261736 | G27: =(D27-E27)/E27 -> -2.1250218e-05

Sheet Cost Center Structure
A1: Level | B1: Code | C1: Cost Center Name | D1: Level 1 Group | E1: Level 2 Group | F1: Level 3 Group | G1: Notes
A2: 0 | B2: 99999 | C2: 99999
A3: 1 | B3: 1 | C3: General areas - production | D3: General areas - production
A4: 2 | B4: 10 | C4: Manufacturing | D4: General areas - production | E4: Manufacturing
A5: 3 | B5: 100 | C5: Manufacturing | D5: General areas - production | E5: Manufacturing | F5: Manufacturing
A6: 2 | B6: 11 | C6: Setup & Deburr | D6: General areas - production | E6: Setup & Deburr
A7: 3 | B7: 110 | C7: Setup & Deburring | D7: General areas - production | E7: Setup & Deburr | F7: Setup & Deburring
A8: 3 | B8: 111 | C8: Cutting | D8: General areas - production | E8: Setup & Deburr | F8: Cutting
A9: 3 | B9: 112 | C9: Brushing | D9: General areas - production | E9: Setup & Deburr | F9: Brushing
A10: 3 | B10: 113 | C10: Belt grinding | D10: General areas - production | E10: Setup & Deburr | F10: Belt grinding
A11: 3 | B11: 114 | C11: Sand blasting | D11: General areas - production | E11: Setup & Deburr | F11: Sand blasting
A12: 3 | B12: 115 | C12: Vibro grinding | D12: General areas - production | E12: Setup & Deburr | F12: Vibro grinding
A13: 3 | B13: 119 | C13: Deburring | D13: General areas - production | E13: Setup & Deburr | F13: Deburring
A14: 2 | B14: 12 | C14: Presses | D14: General areas - production | E14: Presses
A15: 3 | B15: 120 | C15: Presses | D15: General areas - production | E15: Presses | F15: Presses
A16: 3 | B16: 121 | C16: Automatic presses | D16: General areas - production | E16: Presses | F16: Automatic presses
A17: 3 | B17: 122 | C17: Hydraulic presses | D17: General areas - production | E17: Presses | F17: Hydraulic presses
A18: 3 | B18: 123 | C18: Excenter presses | D18: General areas - production | E18: Presses | F18: Excenter presses
A19: 3 | B19: 124 | C19: Production island brushes | D19: General areas - production | E19: Presses | F19: Production island brushes
A20: 3 | B20: 125 | C20: Drilling | D20: General areas - production | E20: Presses | F20: Drilling
A21: 3 | B21: 126 | C21: Miscellaneous press-department | D21: General areas - production | E21: Presses | F21: Miscellaneous press-department
A22: 3 | B22: 127 | C22: Press brake | D22: General areas - production | E22: Presses | F22: Press brake
A23: 2 | B23: 13 | C23: Mechanic | D23: General areas - production | E23: Mechanic
A24: 3 | B24: 130 | C24: Mechanic | D24: General areas - production | E24: Mechanic | F24: Mechanic
A25: 3 | B25: 131 | C25: Cam lathe | D25: General areas - production | E25: Mechanic | F25: Cam lathe
A26: 3 | B26: 132 | C26: NC turning | D26: General areas - production | E26: Mechanic | F26: NC turning
A27: 3 | B27: 133 | C27: Turning | D27: General areas - production | E27: Mechanic | F27: Turning
A28: 3 | B28: 134 | C28: NC milling | D28: General areas - production | E28: Mechanic | F28: NC milling
A29: 3 | B29: 139 | C29: Miscellaneous mechanic | D29: General areas - production | E29: Mechanic | F29: Miscellaneous mechanic
A30: 2 | B30: 14 | C30: Welding | D30: General areas - production | E30: Welding
A31: 3 | B31: 140 | C31: Welding | D31: General areas - production | E31: Welding | F31: Welding
A32: 3 | B32: 142 | C32: Welding robots | D32: General areas - production | E32: Welding | F32: Welding robots
A33: 3 | B33: 148 | C33: Miscellaneous welding | D33: General areas - production | E33: Welding | F33: Miscellaneous welding
A34: 2 | B34: 16 | C34: Assembly | D34: General areas - production | E34: Assembly
A35: 3 | B35: 160 | C35: Assembly | D35: General areas - production | E35: Assembly | F35: Assembly
A36: 3 | B36: 161 | C36: Riveting machines | D36: General areas - production | E36: Assembly | F36: Riveting machines
A37: 3 | B37: 167 | C37: Special equipment assembly | D37: General areas - production | E37: Assembly | F37: Special equipment assembly
A38: 3 | B38: 168 | C38: Special equipment assembly | D38: General areas - production | E38: Assembly | F38: Special equipment assembly
A39: 3 | B39: 169 | C39: Manual workplaces assembly | D39: General areas - production | E39: Assembly | F39: Manual workplaces assembly
A40: 2 | B40: 18 | C40: Injection Molding | D40: General areas - production | E40: Injection Molding
...
